[2024-09-02T23:36:11.752+0000] {local_task_job_runner.py:123} INFO - ::group::Pre task execution logs
[2024-09-02T23:36:11.760+0000] {taskinstance.py:2603} INFO - Dependencies all met for dep_context=non-requeueable deps ti=<TaskInstance: create_insert_table.create_snowflake_table manual__2024-09-02T23:36:04.644123+00:00 [queued]>
[2024-09-02T23:36:11.766+0000] {taskinstance.py:2603} INFO - Dependencies all met for dep_context=requeueable deps ti=<TaskInstance: create_insert_table.create_snowflake_table manual__2024-09-02T23:36:04.644123+00:00 [queued]>
[2024-09-02T23:36:11.766+0000] {taskinstance.py:2856} INFO - Starting attempt 1 of 3
[2024-09-02T23:36:11.782+0000] {taskinstance.py:2879} INFO - Executing <Task(SnowflakeOperator): create_snowflake_table> on 2024-09-02 23:36:04.644123+00:00
[2024-09-02T23:36:11.788+0000] {logging_mixin.py:190} WARNING - /home/ubuntu/airflow_snow/lib/python3.12/site-packages/airflow/task/task_runner/standard_task_runner.py:70 DeprecationWarning: This process (pid=4982) is multi-threaded, use of fork() may lead to deadlocks in the child.
[2024-09-02T23:36:11.789+0000] {standard_task_runner.py:72} INFO - Started process 4986 to run task
[2024-09-02T23:36:11.789+0000] {standard_task_runner.py:104} INFO - Running: ['airflow', 'tasks', 'run', 'create_insert_table', 'create_snowflake_table', 'manual__2024-09-02T23:36:04.644123+00:00', '--job-id', '19', '--raw', '--subdir', 'DAGS_FOLDER/snow_yml.py', '--cfg-path', '/tmp/tmpmxwqm139']
[2024-09-02T23:36:11.791+0000] {standard_task_runner.py:105} INFO - Job 19: Subtask create_snowflake_table
[2024-09-02T23:36:11.827+0000] {task_command.py:467} INFO - Running <TaskInstance: create_insert_table.create_snowflake_table manual__2024-09-02T23:36:04.644123+00:00 [running]> on host ip-172-31-84-185.ec2.internal
[2024-09-02T23:36:11.883+0000] {taskinstance.py:3122} INFO - Exporting env vars: AIRFLOW_CTX_DAG_EMAIL='myemail@domain.com' AIRFLOW_CTX_DAG_OWNER='airflow' AIRFLOW_CTX_DAG_ID='create_insert_table' AIRFLOW_CTX_TASK_ID='create_snowflake_table' AIRFLOW_CTX_EXECUTION_DATE='2024-09-02T23:36:04.644123+00:00' AIRFLOW_CTX_TRY_NUMBER='1' AIRFLOW_CTX_DAG_RUN_ID='manual__2024-09-02T23:36:04.644123+00:00'
[2024-09-02T23:36:11.884+0000] {taskinstance.py:731} INFO - ::endgroup::
[2024-09-02T23:36:11.896+0000] {sql.py:266} INFO - Executing: CREATE TABLE IF NOT EXISTS student_info(
                student_id INTEGER NOT NULL,
                fname VARCHAR(255) NOT NULL,
                lname VARCHAR(255) NOT NULL,
                email VARCHAR(300) NOT NULL UNIQUE,
                subject VARCHAR(255) NOT NULL,
                score NUMERIC NOT NULL DEFAULT 0	
            )
            
[2024-09-02T23:36:11.902+0000] {base.py:84} INFO - Retrieving connection 'conn_id_snowflake'
[2024-09-02T23:36:11.922+0000] {base.py:84} INFO - Retrieving connection 'conn_id_snowflake'
[2024-09-02T23:36:11.922+0000] {connection.py:413} INFO - Snowflake Connector for Python Version: 3.12.1, Python Version: 3.12.3, Platform: Linux-6.8.0-1014-aws-x86_64-with-glibc2.39
[2024-09-02T23:36:11.923+0000] {connection.py:1196} INFO - Connecting to GLOBAL Snowflake domain
[2024-09-02T23:36:11.923+0000] {connection.py:1277} INFO - This connection is in OCSP Fail Open Mode. TLS Certificates would be checked for validity and revocation status. Any other Certificate Revocation related exceptions or OCSP Responder failures would be disregarded in favor of connectivity.
[2024-09-02T23:36:11.927+0000] {connectionpool.py:824} WARNING - Retrying (Retry(total=0, connect=None, read=None, redirect=None, status=None)) after connection broken by 'NewConnectionError('<snowflake.connector.vendored.urllib3.connection.HTTPSConnection object at 0x732c3df77a40>: Failed to establish a new connection: [Errno -2] Name or service not known')': /session/v1/login-request?request_id=38556a07-5200-47e3-bb6c-20bc3ce33a85&databaseName=student_database&schemaName=student_schema&warehouse=student_warehouse&roleName=ACCOUNTADMIN&request_guid=facd3d46-9b5e-4997-9937-47edd6daf0e3
[2024-09-02T23:36:12.930+0000] {connectionpool.py:824} WARNING - Retrying (Retry(total=0, connect=None, read=None, redirect=None, status=None)) after connection broken by 'NewConnectionError('<snowflake.connector.vendored.urllib3.connection.HTTPSConnection object at 0x732c3dddf4d0>: Failed to establish a new connection: [Errno -2] Name or service not known')': /session/v1/login-request?request_id=5a51d1db-0701-4364-8848-7506f7b2acf1&databaseName=student_database&schemaName=student_schema&warehouse=student_warehouse&roleName=ACCOUNTADMIN&request_guid=470524de-cd42-49a5-b546-2d42baed5571
[2024-09-02T23:36:12.932+0000] {taskinstance.py:3301} ERROR - Task failed with exception
Traceback (most recent call last):
  File "/home/ubuntu/airflow_snow/lib/python3.12/site-packages/snowflake/connector/vendored/urllib3/connection.py", line 174, in _new_conn
    conn = connection.create_connection(
           ^^^^^^^^^^^^^^^^^^^^^^^^^^^^^
  File "/home/ubuntu/airflow_snow/lib/python3.12/site-packages/snowflake/connector/vendored/urllib3/util/connection.py", line 79, in create_connection
    for res in socket.getaddrinfo(host, port, family, socket.SOCK_STREAM):
               ^^^^^^^^^^^^^^^^^^^^^^^^^^^^^^^^^^^^^^^^^^^^^^^^^^^^^^^^^^
  File "/usr/lib/python3.12/socket.py", line 963, in getaddrinfo
    for res in _socket.getaddrinfo(host, port, family, type, proto, flags):
               ^^^^^^^^^^^^^^^^^^^^^^^^^^^^^^^^^^^^^^^^^^^^^^^^^^^^^^^^^^^
socket.gaierror: [Errno -2] Name or service not known

During handling of the above exception, another exception occurred:

Traceback (most recent call last):
  File "/home/ubuntu/airflow_snow/lib/python3.12/site-packages/snowflake/connector/vendored/urllib3/connectionpool.py", line 715, in urlopen
    httplib_response = self._make_request(
                       ^^^^^^^^^^^^^^^^^^^
  File "/home/ubuntu/airflow_snow/lib/python3.12/site-packages/snowflake/connector/vendored/urllib3/connectionpool.py", line 404, in _make_request
    self._validate_conn(conn)
  File "/home/ubuntu/airflow_snow/lib/python3.12/site-packages/snowflake/connector/vendored/urllib3/connectionpool.py", line 1058, in _validate_conn
    conn.connect()
  File "/home/ubuntu/airflow_snow/lib/python3.12/site-packages/snowflake/connector/vendored/urllib3/connection.py", line 363, in connect
    self.sock = conn = self._new_conn()
                       ^^^^^^^^^^^^^^^^
  File "/home/ubuntu/airflow_snow/lib/python3.12/site-packages/snowflake/connector/vendored/urllib3/connection.py", line 186, in _new_conn
    raise NewConnectionError(
snowflake.connector.vendored.urllib3.exceptions.NewConnectionError: <snowflake.connector.vendored.urllib3.connection.HTTPSConnection object at 0x732c3ddde720>: Failed to establish a new connection: [Errno -2] Name or service not known

During handling of the above exception, another exception occurred:

Traceback (most recent call last):
  File "/home/ubuntu/airflow_snow/lib/python3.12/site-packages/snowflake/connector/vendored/requests/adapters.py", line 486, in send
    resp = conn.urlopen(
           ^^^^^^^^^^^^^
  File "/home/ubuntu/airflow_snow/lib/python3.12/site-packages/snowflake/connector/vendored/urllib3/connectionpool.py", line 827, in urlopen
    return self.urlopen(
           ^^^^^^^^^^^^^
  File "/home/ubuntu/airflow_snow/lib/python3.12/site-packages/snowflake/connector/vendored/urllib3/connectionpool.py", line 799, in urlopen
    retries = retries.increment(
              ^^^^^^^^^^^^^^^^^^
  File "/home/ubuntu/airflow_snow/lib/python3.12/site-packages/snowflake/connector/vendored/urllib3/util/retry.py", line 592, in increment
    raise MaxRetryError(_pool, url, error or ResponseError(cause))
snowflake.connector.vendored.urllib3.exceptions.MaxRetryError: HTTPSConnectionPool(host='ajb95358.us%20east%20(n.%20virginia).snowflakecomputing.com', port=443): Max retries exceeded with url: /session/v1/login-request?request_id=38556a07-5200-47e3-bb6c-20bc3ce33a85&databaseName=student_database&schemaName=student_schema&warehouse=student_warehouse&roleName=ACCOUNTADMIN&request_guid=facd3d46-9b5e-4997-9937-47edd6daf0e3 (Caused by NewConnectionError('<snowflake.connector.vendored.urllib3.connection.HTTPSConnection object at 0x732c3ddde720>: Failed to establish a new connection: [Errno -2] Name or service not known'))

During handling of the above exception, another exception occurred:

Traceback (most recent call last):
  File "/home/ubuntu/airflow_snow/lib/python3.12/site-packages/snowflake/connector/network.py", line 1059, in _request_exec
    raw_ret = session.request(
              ^^^^^^^^^^^^^^^^
  File "/home/ubuntu/airflow_snow/lib/python3.12/site-packages/snowflake/connector/vendored/requests/sessions.py", line 589, in request
    resp = self.send(prep, **send_kwargs)
           ^^^^^^^^^^^^^^^^^^^^^^^^^^^^^^
  File "/home/ubuntu/airflow_snow/lib/python3.12/site-packages/snowflake/connector/vendored/requests/sessions.py", line 703, in send
    r = adapter.send(request, **kwargs)
        ^^^^^^^^^^^^^^^^^^^^^^^^^^^^^^^
  File "/home/ubuntu/airflow_snow/lib/python3.12/site-packages/snowflake/connector/vendored/requests/adapters.py", line 519, in send
    raise ConnectionError(e, request=request)
snowflake.connector.vendored.requests.exceptions.ConnectionError: HTTPSConnectionPool(host='ajb95358.us%20east%20(n.%20virginia).snowflakecomputing.com', port=443): Max retries exceeded with url: /session/v1/login-request?request_id=38556a07-5200-47e3-bb6c-20bc3ce33a85&databaseName=student_database&schemaName=student_schema&warehouse=student_warehouse&roleName=ACCOUNTADMIN&request_guid=facd3d46-9b5e-4997-9937-47edd6daf0e3 (Caused by NewConnectionError('<snowflake.connector.vendored.urllib3.connection.HTTPSConnection object at 0x732c3ddde720>: Failed to establish a new connection: [Errno -2] Name or service not known'))

During handling of the above exception, another exception occurred:

Traceback (most recent call last):
  File "/home/ubuntu/airflow_snow/lib/python3.12/site-packages/snowflake/connector/connection.py", line 1414, in _authenticate
    auth.authenticate(
  File "/home/ubuntu/airflow_snow/lib/python3.12/site-packages/snowflake/connector/auth/_auth.py", line 250, in authenticate
    ret = self._rest._post_request(
          ^^^^^^^^^^^^^^^^^^^^^^^^^
  File "/home/ubuntu/airflow_snow/lib/python3.12/site-packages/snowflake/connector/network.py", line 739, in _post_request
    ret = self.fetch(
          ^^^^^^^^^^^
  File "/home/ubuntu/airflow_snow/lib/python3.12/site-packages/snowflake/connector/network.py", line 854, in fetch
    ret = self._request_exec_wrapper(
          ^^^^^^^^^^^^^^^^^^^^^^^^^^^
  File "/home/ubuntu/airflow_snow/lib/python3.12/site-packages/snowflake/connector/network.py", line 971, in _request_exec_wrapper
    raise e
  File "/home/ubuntu/airflow_snow/lib/python3.12/site-packages/snowflake/connector/network.py", line 896, in _request_exec_wrapper
    return_object = self._request_exec(
                    ^^^^^^^^^^^^^^^^^^^
  File "/home/ubuntu/airflow_snow/lib/python3.12/site-packages/snowflake/connector/network.py", line 1144, in _request_exec
    raise OperationalError(
snowflake.connector.errors.OperationalError: 251011: 251011: ConnectionTimeout occurred during login. Will be handled by authenticator

The above exception was the direct cause of the following exception:

Traceback (most recent call last):
  File "/home/ubuntu/airflow_snow/lib/python3.12/site-packages/airflow/models/taskinstance.py", line 767, in _execute_task
    result = _execute_callable(context=context, **execute_callable_kwargs)
             ^^^^^^^^^^^^^^^^^^^^^^^^^^^^^^^^^^^^^^^^^^^^^^^^^^^^^^^^^^^^^
  File "/home/ubuntu/airflow_snow/lib/python3.12/site-packages/airflow/models/taskinstance.py", line 733, in _execute_callable
    return ExecutionCallableRunner(
           ^^^^^^^^^^^^^^^^^^^^^^^^
  File "/home/ubuntu/airflow_snow/lib/python3.12/site-packages/airflow/utils/operator_helpers.py", line 252, in run
    return self.func(*args, **kwargs)
           ^^^^^^^^^^^^^^^^^^^^^^^^^^
  File "/home/ubuntu/airflow_snow/lib/python3.12/site-packages/airflow/models/baseoperator.py", line 406, in wrapper
    return func(self, *args, **kwargs)
           ^^^^^^^^^^^^^^^^^^^^^^^^^^^
  File "/home/ubuntu/airflow_snow/lib/python3.12/site-packages/airflow/providers/common/sql/operators/sql.py", line 272, in execute
    output = hook.run(
             ^^^^^^^^^
  File "/home/ubuntu/airflow_snow/lib/python3.12/site-packages/airflow/providers/snowflake/hooks/snowflake.py", line 404, in run
    with closing(self.get_conn()) as conn:
                 ^^^^^^^^^^^^^^^
  File "/home/ubuntu/airflow_snow/lib/python3.12/site-packages/airflow/providers/snowflake/hooks/snowflake.py", line 300, in get_conn
    conn = connector.connect(**conn_config)
           ^^^^^^^^^^^^^^^^^^^^^^^^^^^^^^^^
  File "/home/ubuntu/airflow_snow/lib/python3.12/site-packages/snowflake/connector/__init__.py", line 55, in Connect
    return SnowflakeConnection(**kwargs)
           ^^^^^^^^^^^^^^^^^^^^^^^^^^^^^
  File "/home/ubuntu/airflow_snow/lib/python3.12/site-packages/snowflake/connector/connection.py", line 456, in __init__
    self.connect(**kwargs)
  File "/home/ubuntu/airflow_snow/lib/python3.12/site-packages/snowflake/connector/connection.py", line 771, in connect
    self.__open_connection()
  File "/home/ubuntu/airflow_snow/lib/python3.12/site-packages/snowflake/connector/connection.py", line 1099, in __open_connection
    self.authenticate_with_retry(self.auth_class)
  File "/home/ubuntu/airflow_snow/lib/python3.12/site-packages/snowflake/connector/connection.py", line 1386, in authenticate_with_retry
    self._authenticate(auth_instance)
  File "/home/ubuntu/airflow_snow/lib/python3.12/site-packages/snowflake/connector/connection.py", line 1458, in _authenticate
    raise auth_op from e
  File "/home/ubuntu/airflow_snow/lib/python3.12/site-packages/snowflake/connector/connection.py", line 1435, in _authenticate
    auth_instance.handle_timeout(
  File "/home/ubuntu/airflow_snow/lib/python3.12/site-packages/snowflake/connector/auth/by_plugin.py", line 212, in handle_timeout
    raise error
snowflake.connector.errors.OperationalError: 250001: 250001: Could not connect to Snowflake backend after 2 attempt(s).Aborting
[2024-09-02T23:36:12.940+0000] {taskinstance.py:1225} INFO - Marking task as UP_FOR_RETRY. dag_id=create_insert_table, task_id=create_snowflake_table, run_id=manual__2024-09-02T23:36:04.644123+00:00, execution_date=20240902T233604, start_date=20240902T233611, end_date=20240902T233612
[2024-09-02T23:36:12.959+0000] {taskinstance.py:340} INFO - ::group::Post task execution logs
[2024-09-02T23:36:12.959+0000] {standard_task_runner.py:124} ERROR - Failed to execute job 19 for task create_snowflake_table (250001: 250001: Could not connect to Snowflake backend after 2 attempt(s).Aborting; 4986)
Traceback (most recent call last):
  File "/home/ubuntu/airflow_snow/lib/python3.12/site-packages/snowflake/connector/vendored/urllib3/connection.py", line 174, in _new_conn
    conn = connection.create_connection(
           ^^^^^^^^^^^^^^^^^^^^^^^^^^^^^
  File "/home/ubuntu/airflow_snow/lib/python3.12/site-packages/snowflake/connector/vendored/urllib3/util/connection.py", line 79, in create_connection
    for res in socket.getaddrinfo(host, port, family, socket.SOCK_STREAM):
               ^^^^^^^^^^^^^^^^^^^^^^^^^^^^^^^^^^^^^^^^^^^^^^^^^^^^^^^^^^
  File "/usr/lib/python3.12/socket.py", line 963, in getaddrinfo
    for res in _socket.getaddrinfo(host, port, family, type, proto, flags):
               ^^^^^^^^^^^^^^^^^^^^^^^^^^^^^^^^^^^^^^^^^^^^^^^^^^^^^^^^^^^
socket.gaierror: [Errno -2] Name or service not known

During handling of the above exception, another exception occurred:

Traceback (most recent call last):
  File "/home/ubuntu/airflow_snow/lib/python3.12/site-packages/snowflake/connector/vendored/urllib3/connectionpool.py", line 715, in urlopen
    httplib_response = self._make_request(
                       ^^^^^^^^^^^^^^^^^^^
  File "/home/ubuntu/airflow_snow/lib/python3.12/site-packages/snowflake/connector/vendored/urllib3/connectionpool.py", line 404, in _make_request
    self._validate_conn(conn)
  File "/home/ubuntu/airflow_snow/lib/python3.12/site-packages/snowflake/connector/vendored/urllib3/connectionpool.py", line 1058, in _validate_conn
    conn.connect()
  File "/home/ubuntu/airflow_snow/lib/python3.12/site-packages/snowflake/connector/vendored/urllib3/connection.py", line 363, in connect
    self.sock = conn = self._new_conn()
                       ^^^^^^^^^^^^^^^^
  File "/home/ubuntu/airflow_snow/lib/python3.12/site-packages/snowflake/connector/vendored/urllib3/connection.py", line 186, in _new_conn
    raise NewConnectionError(
snowflake.connector.vendored.urllib3.exceptions.NewConnectionError: <snowflake.connector.vendored.urllib3.connection.HTTPSConnection object at 0x732c3ddde720>: Failed to establish a new connection: [Errno -2] Name or service not known

During handling of the above exception, another exception occurred:

Traceback (most recent call last):
  File "/home/ubuntu/airflow_snow/lib/python3.12/site-packages/snowflake/connector/vendored/requests/adapters.py", line 486, in send
    resp = conn.urlopen(
           ^^^^^^^^^^^^^
  File "/home/ubuntu/airflow_snow/lib/python3.12/site-packages/snowflake/connector/vendored/urllib3/connectionpool.py", line 827, in urlopen
    return self.urlopen(
           ^^^^^^^^^^^^^
  File "/home/ubuntu/airflow_snow/lib/python3.12/site-packages/snowflake/connector/vendored/urllib3/connectionpool.py", line 799, in urlopen
    retries = retries.increment(
              ^^^^^^^^^^^^^^^^^^
  File "/home/ubuntu/airflow_snow/lib/python3.12/site-packages/snowflake/connector/vendored/urllib3/util/retry.py", line 592, in increment
    raise MaxRetryError(_pool, url, error or ResponseError(cause))
snowflake.connector.vendored.urllib3.exceptions.MaxRetryError: HTTPSConnectionPool(host='ajb95358.us%20east%20(n.%20virginia).snowflakecomputing.com', port=443): Max retries exceeded with url: /session/v1/login-request?request_id=38556a07-5200-47e3-bb6c-20bc3ce33a85&databaseName=student_database&schemaName=student_schema&warehouse=student_warehouse&roleName=ACCOUNTADMIN&request_guid=facd3d46-9b5e-4997-9937-47edd6daf0e3 (Caused by NewConnectionError('<snowflake.connector.vendored.urllib3.connection.HTTPSConnection object at 0x732c3ddde720>: Failed to establish a new connection: [Errno -2] Name or service not known'))

During handling of the above exception, another exception occurred:

Traceback (most recent call last):
  File "/home/ubuntu/airflow_snow/lib/python3.12/site-packages/snowflake/connector/network.py", line 1059, in _request_exec
    raw_ret = session.request(
              ^^^^^^^^^^^^^^^^
  File "/home/ubuntu/airflow_snow/lib/python3.12/site-packages/snowflake/connector/vendored/requests/sessions.py", line 589, in request
    resp = self.send(prep, **send_kwargs)
           ^^^^^^^^^^^^^^^^^^^^^^^^^^^^^^
  File "/home/ubuntu/airflow_snow/lib/python3.12/site-packages/snowflake/connector/vendored/requests/sessions.py", line 703, in send
    r = adapter.send(request, **kwargs)
        ^^^^^^^^^^^^^^^^^^^^^^^^^^^^^^^
  File "/home/ubuntu/airflow_snow/lib/python3.12/site-packages/snowflake/connector/vendored/requests/adapters.py", line 519, in send
    raise ConnectionError(e, request=request)
snowflake.connector.vendored.requests.exceptions.ConnectionError: HTTPSConnectionPool(host='ajb95358.us%20east%20(n.%20virginia).snowflakecomputing.com', port=443): Max retries exceeded with url: /session/v1/login-request?request_id=38556a07-5200-47e3-bb6c-20bc3ce33a85&databaseName=student_database&schemaName=student_schema&warehouse=student_warehouse&roleName=ACCOUNTADMIN&request_guid=facd3d46-9b5e-4997-9937-47edd6daf0e3 (Caused by NewConnectionError('<snowflake.connector.vendored.urllib3.connection.HTTPSConnection object at 0x732c3ddde720>: Failed to establish a new connection: [Errno -2] Name or service not known'))

During handling of the above exception, another exception occurred:

Traceback (most recent call last):
  File "/home/ubuntu/airflow_snow/lib/python3.12/site-packages/snowflake/connector/connection.py", line 1414, in _authenticate
    auth.authenticate(
  File "/home/ubuntu/airflow_snow/lib/python3.12/site-packages/snowflake/connector/auth/_auth.py", line 250, in authenticate
    ret = self._rest._post_request(
          ^^^^^^^^^^^^^^^^^^^^^^^^^
  File "/home/ubuntu/airflow_snow/lib/python3.12/site-packages/snowflake/connector/network.py", line 739, in _post_request
    ret = self.fetch(
          ^^^^^^^^^^^
  File "/home/ubuntu/airflow_snow/lib/python3.12/site-packages/snowflake/connector/network.py", line 854, in fetch
    ret = self._request_exec_wrapper(
          ^^^^^^^^^^^^^^^^^^^^^^^^^^^
  File "/home/ubuntu/airflow_snow/lib/python3.12/site-packages/snowflake/connector/network.py", line 971, in _request_exec_wrapper
    raise e
  File "/home/ubuntu/airflow_snow/lib/python3.12/site-packages/snowflake/connector/network.py", line 896, in _request_exec_wrapper
    return_object = self._request_exec(
                    ^^^^^^^^^^^^^^^^^^^
  File "/home/ubuntu/airflow_snow/lib/python3.12/site-packages/snowflake/connector/network.py", line 1144, in _request_exec
    raise OperationalError(
snowflake.connector.errors.OperationalError: 251011: 251011: ConnectionTimeout occurred during login. Will be handled by authenticator

The above exception was the direct cause of the following exception:

Traceback (most recent call last):
  File "/home/ubuntu/airflow_snow/lib/python3.12/site-packages/airflow/task/task_runner/standard_task_runner.py", line 117, in _start_by_fork
    ret = args.func(args, dag=self.dag)
          ^^^^^^^^^^^^^^^^^^^^^^^^^^^^^
  File "/home/ubuntu/airflow_snow/lib/python3.12/site-packages/airflow/cli/cli_config.py", line 49, in command
    return func(*args, **kwargs)
           ^^^^^^^^^^^^^^^^^^^^^
  File "/home/ubuntu/airflow_snow/lib/python3.12/site-packages/airflow/utils/cli.py", line 115, in wrapper
    return f(*args, **kwargs)
           ^^^^^^^^^^^^^^^^^^
  File "/home/ubuntu/airflow_snow/lib/python3.12/site-packages/airflow/cli/commands/task_command.py", line 483, in task_run
    task_return_code = _run_task_by_selected_method(args, _dag, ti)
                       ^^^^^^^^^^^^^^^^^^^^^^^^^^^^^^^^^^^^^^^^^^^^
  File "/home/ubuntu/airflow_snow/lib/python3.12/site-packages/airflow/cli/commands/task_command.py", line 256, in _run_task_by_selected_method
    return _run_raw_task(args, ti)
           ^^^^^^^^^^^^^^^^^^^^^^^
  File "/home/ubuntu/airflow_snow/lib/python3.12/site-packages/airflow/cli/commands/task_command.py", line 341, in _run_raw_task
    return ti._run_raw_task(
           ^^^^^^^^^^^^^^^^^
  File "/home/ubuntu/airflow_snow/lib/python3.12/site-packages/airflow/utils/session.py", line 97, in wrapper
    return func(*args, session=session, **kwargs)
           ^^^^^^^^^^^^^^^^^^^^^^^^^^^^^^^^^^^^^^
  File "/home/ubuntu/airflow_snow/lib/python3.12/site-packages/airflow/models/taskinstance.py", line 2995, in _run_raw_task
    return _run_raw_task(
           ^^^^^^^^^^^^^^
  File "/home/ubuntu/airflow_snow/lib/python3.12/site-packages/airflow/models/taskinstance.py", line 273, in _run_raw_task
    TaskInstance._execute_task_with_callbacks(
  File "/home/ubuntu/airflow_snow/lib/python3.12/site-packages/airflow/models/taskinstance.py", line 3149, in _execute_task_with_callbacks
    result = self._execute_task(context, task_orig)
             ^^^^^^^^^^^^^^^^^^^^^^^^^^^^^^^^^^^^^^
  File "/home/ubuntu/airflow_snow/lib/python3.12/site-packages/airflow/models/taskinstance.py", line 3173, in _execute_task
    return _execute_task(self, context, task_orig)
           ^^^^^^^^^^^^^^^^^^^^^^^^^^^^^^^^^^^^^^^
  File "/home/ubuntu/airflow_snow/lib/python3.12/site-packages/airflow/models/taskinstance.py", line 767, in _execute_task
    result = _execute_callable(context=context, **execute_callable_kwargs)
             ^^^^^^^^^^^^^^^^^^^^^^^^^^^^^^^^^^^^^^^^^^^^^^^^^^^^^^^^^^^^^
  File "/home/ubuntu/airflow_snow/lib/python3.12/site-packages/airflow/models/taskinstance.py", line 733, in _execute_callable
    return ExecutionCallableRunner(
           ^^^^^^^^^^^^^^^^^^^^^^^^
  File "/home/ubuntu/airflow_snow/lib/python3.12/site-packages/airflow/utils/operator_helpers.py", line 252, in run
    return self.func(*args, **kwargs)
           ^^^^^^^^^^^^^^^^^^^^^^^^^^
  File "/home/ubuntu/airflow_snow/lib/python3.12/site-packages/airflow/models/baseoperator.py", line 406, in wrapper
    return func(self, *args, **kwargs)
           ^^^^^^^^^^^^^^^^^^^^^^^^^^^
  File "/home/ubuntu/airflow_snow/lib/python3.12/site-packages/airflow/providers/common/sql/operators/sql.py", line 272, in execute
    output = hook.run(
             ^^^^^^^^^
  File "/home/ubuntu/airflow_snow/lib/python3.12/site-packages/airflow/providers/snowflake/hooks/snowflake.py", line 404, in run
    with closing(self.get_conn()) as conn:
                 ^^^^^^^^^^^^^^^
  File "/home/ubuntu/airflow_snow/lib/python3.12/site-packages/airflow/providers/snowflake/hooks/snowflake.py", line 300, in get_conn
    conn = connector.connect(**conn_config)
           ^^^^^^^^^^^^^^^^^^^^^^^^^^^^^^^^
  File "/home/ubuntu/airflow_snow/lib/python3.12/site-packages/snowflake/connector/__init__.py", line 55, in Connect
    return SnowflakeConnection(**kwargs)
           ^^^^^^^^^^^^^^^^^^^^^^^^^^^^^
  File "/home/ubuntu/airflow_snow/lib/python3.12/site-packages/snowflake/connector/connection.py", line 456, in __init__
    self.connect(**kwargs)
  File "/home/ubuntu/airflow_snow/lib/python3.12/site-packages/snowflake/connector/connection.py", line 771, in connect
    self.__open_connection()
  File "/home/ubuntu/airflow_snow/lib/python3.12/site-packages/snowflake/connector/connection.py", line 1099, in __open_connection
    self.authenticate_with_retry(self.auth_class)
  File "/home/ubuntu/airflow_snow/lib/python3.12/site-packages/snowflake/connector/connection.py", line 1386, in authenticate_with_retry
    self._authenticate(auth_instance)
  File "/home/ubuntu/airflow_snow/lib/python3.12/site-packages/snowflake/connector/connection.py", line 1458, in _authenticate
    raise auth_op from e
  File "/home/ubuntu/airflow_snow/lib/python3.12/site-packages/snowflake/connector/connection.py", line 1435, in _authenticate
    auth_instance.handle_timeout(
  File "/home/ubuntu/airflow_snow/lib/python3.12/site-packages/snowflake/connector/auth/by_plugin.py", line 212, in handle_timeout
    raise error
snowflake.connector.errors.OperationalError: 250001: 250001: Could not connect to Snowflake backend after 2 attempt(s).Aborting
[2024-09-02T23:36:12.970+0000] {local_task_job_runner.py:261} INFO - Task exited with return code 1
[2024-09-02T23:36:12.976+0000] {logging_mixin.py:190} WARNING - /home/ubuntu/airflow_snow/lib/python3.12/site-packages/airflow/models/baseoperator.py:1378 AirflowProviderDeprecationWarning: Call to deprecated class SnowflakeOperator. (This class is deprecated. Please use `airflow.providers.common.sql.operators.sql.SQLExecuteQueryOperator`. Also, you can provide `hook_params={'warehouse': <warehouse>, 'database': <database>, 'role': <role>, 'schema': <schema>, 'authenticator': <authenticator>,'session_parameters': <session_parameters>}`.)
[2024-09-02T23:36:12.985+0000] {taskinstance.py:3891} INFO - 0 downstream tasks scheduled from follow-on schedule check
[2024-09-02T23:36:12.986+0000] {local_task_job_runner.py:240} INFO - ::endgroup::
